Workbook

Sheet DATA_ADN
A1: id_multitabla | B1: codigo_tabla | C1: nombre_tabla | D1: codigo | E1: orden | F1: valor | G1: valor_aux | H1: valor_crm | I1: valor_flex | J1: estado | K1: estado_tabla | L1: usuario_crea | M1: fecha_crea | N1: usuario_modif | O1: fecha_modif
A2: 455 | B2: 001 | C2: Tipo de Documento Identidad | D2: NULL | E2: NULL | F2: NULL | G2: NULL | H2: NULL | I2: NULL | J2: NULL | K2: 1 | L2: admin | M2: 43606.789 | N2: NULL | O2: NULL
A3: 456 | B3: 001 | C3: Tipo de Documento Identidad | D3: 1 | E3: 1 | F3: DNI | G3: NULL | H3: 538560000 | I3: D | J3: 1 | K3: 1 | L3: admin | M3: 43606.789 | N3: NULL | O3: NULL
A4: 457 | B4: 001 | C4: Tipo de Documento Identidad | D4: 2 | E4: 2 | F4: Carnet ExtranjerÃ­a | G4: NULL | H4: 538560001 | I4: E | J4: 1 | K4: 1 | L4: admin | M4: 43606.789 | N4: NULL | O4: NULL
A5: 458 | B5: 001 | C5: Tipo de Documento Identidad | D5: 3 | E5: 3 | F5: Carnet Identidad Policial | G5: NULL | H5: 538560002 | I5: I | J5: 2 | K5: 1 | L5: admin | M5: 43606.789 | N5: NULL | O5: NULL
A6: 459 | B6: 001 | C6: Tipo de Documento Identidad | D6: 4 | E6: 4 | F6: Carnet de AutorizaciÃ³n | G6: NULL | H6: 538560003 | I6: M | J6: 2 | K6: 1 | L6: admin | M6: 43606.789 | N6: NULL | O6: NULL
A7: 460 | B7: 001 | C7: Tipo de Documento Identidad | D7: 5 | E7: 5 | F7: Pasaporte | G7: NULL | H7: 538560004 | I7: P | J7: 2 | K7: 1 | L7: admin | M7: 43606.789 | N7: NULL | O7: NULL
A8: 461 | B8: 001 | C8: Tipo de Documento Identidad | D8: 6 | E8: 6 | F8: Licencia de Conducir | G8: NULL | H8: 538560005 | I8: K | J8: 2 | K8: 1 | L8: admin | M8: 43606.789 | N8: NULL | O8: NULL
A9: 462 | B9: 001 | C9: Tipo de Documento Identidad | D9: 7 | E9: 7 | F9: Libreta Electoral | G9: NULL | H9: 538560006 | I9: L | J9: 2 | K9: 1 | L9: admin | M9: 43606.789 | N9: NULL | O9: NULL
A10: 463 | B10: 001 | C10: Tipo de Documento Identidad | D10: 8 | E10: 8 | F10: Partida Nacimiento | G10: NULL | H10: 538560007 | I10: N | J10: 2 | K10: 1 | L10: admin | M10: 43606.789 | N10: NULL | O10: NULL
A11: 464 | B11: 001 | C11: Tipo de Documento Identidad | D11: 9 | E11: 9 | F11: Otro Documento | G11: NULL | H11: 538560008 | J11: 2 | K11: 1 | L11: admin | M11: 43606.789 | N11: NULL | O11: NULL
A12: 465 | B12: 001 | C12: Tipo de Documento Identidad | D12: 10 | E12: 10 | F12: RUC Persona Natural | G12: NULL | H12: 538560009 | I12: R | J12: 2 | K12: 1 | L12: admin | M12: 43606.789 | N12: NULL | O12: NULL
A13: 466 | B13: 001 | C13: Tipo de Documento Identidad | D13: 11 | E13: 11 | F13: RUC Persona JurÃ­dica | G13: NULL | H13: 538560011 | I13: J | J13: 2 | K13: 1 | L13: admin | M13: 43606.789 | N13: NULL | O13: NULL
A14: 467 | B14: 001 | C14: Tipo de Documento Identidad | D14: 12 | E14: 12 | F14: Sin Documento | G14: NULL | H14: 538560010 | I14: S | J14: 2 | K14: 1 | L14: admin | M14: 43606.789 | N14: NULL | O14: NULL
A15: 468 | B15: 002 | C15: GÃ©nero | D15: NULL | E15: NULL | F15: NULL | G15: NULL | H15: NULL | I15: NULL | J15: NULL | K15: 1 | L15: admin | M15: 43606.789 | N15: NULL | O15: NULL
A16: 469 | B16: 002 | C16: GÃ©nero | D16: 1 | E16: 1 | F16: Masculino | G16: NULL | H16: 538560000 | I16: M | J16: 1 | K16: 1 | L16: admin | M16: 43606.789 | N16: NULL | O16: NULL
A17: 470 | B17: 002 | C17: GÃ©nero | D17: 2 | E17: 2 | F17: Femenino | G17: NULL | H17: 538560001 | I17: F | J17: 1 | K17: 1 | L17: admin | M17: 43606.789 | N17: NULL | O17: NULL
A18: 471 | B18: 002 | C18: GÃ©nero | D18: 3 | E18: 3 | F18: Desconocido | G18: NULL | H18: 538560002 | I18: NULL | J18: 2 | K18: 1 | L18: admin | M18: 43606.789 | N18: NULL | O18: NULL
A19: 472 | B19: 003 | C19: ProfesiÃ³n | D19: NULL | E19: NULL | F19: NULL | G19: NULL | H19: NULL | I19: NULL | J19: NULL | K19: 1 | L19: admin | M19: 43606.789 | N19: NULL | O19: NULL
A20: 473 | B20: 003 | C20: ProfesiÃ³n | D20: 1 | E20: 1 | F20: Abogados (no penalistas) | G20: NULL | H20: 1 | I20: NULL | J20: 1 | K20: 1 | L20: admin | M20: 43606.789 | N20: NULL | O20: NULL
A21: 474 | B21: 003 | C21: ProfesiÃ³n | D21: 2 | E21: 2 | F21: Actuarios | G21: NULL | H21: 2 | I21: NULL | J21: 1 | K21: 1 | L21: admin | M21: 43606.789 | N21: NULL | O21: NULL
A22: 475 | B22: 003 | C22: ProfesiÃ³n | D22: 3 | E22: 3 | F22: Administrador | G22: NULL | H22: 3 | I22: NULL | J22: 1 | K22: 1 | L22: admin | M22: 43606.789 | N22: NULL | O22: NULL
A23: 476 | B23: 003 | C23: ProfesiÃ³n | D23: 4 | E23: 4 | F23: Ala Delta | G23: NULL | H23: 4 | I23: NULL | J23: 1 | K23: 1 | L23: admin | M23: 43606.789 | N23: NULL | O23: NULL
A24: 477 | B24: 003 | C24: ProfesiÃ³n | D24: 5 | E24: 5 | F24: AlbaÃ±iles | G24: NULL | H24: 5 | I24: NULL | J24: 1 | K24: 1 | L24: admin | M24: 43606.789 | N24: NULL | O24: NULL
A25: 478 | B25: 003 | C25: ProfesiÃ³n | D25: 6 | E25: 6 | F25: Arquitecto (obra) | G25: NULL | H25: 6 | I25: NULL | J25: 1 | K25: 1 | L25: admin | M25: 43606.789 | N25: NULL | O25: NULL
A26: 479 | B26: 003 | C26: ProfesiÃ³n | D26: 7 | E26: 7 | F26: Arquitecto (sin ingreso a obra) | G26: NULL | H26: 7 | I26: NULL | J26: 1 | K26: 1 | L26: admin | M26: 43606.789 | N26: NULL | O26: NULL
A27: 480 | B27: 003 | C27: ProfesiÃ³n | D27: 8 | E27: 8 | F27: Artista PlÃ¡stico | G27: NULL | H27: 8 | I27: NULL | J27: 1 | K27: 1 | L27: admin | M27: 43606.789 | N27: NULL | O27: NULL
A28: 481 | B28: 003 | C28: ProfesiÃ³n | D28: 9 | E28: 9 | F28: Asesores | G28: NULL | H28: 9 | I28: NULL | J28: 1 | K28: 1 | L28: admin | M28: 43606.789 | N28: NULL | O28: NULL
A29: 482 | B29: 003 | C29: ProfesiÃ³n | D29: 10 | E29: 10 | F29: Auxiliares Administrativos | G29: NULL | H29: 10 | I29: NULL | J29: 1 | K29: 1 | L29: admin | M29: 43606.789 | N29: NULL | O29: NULL
A30: 483 | B30: 003 | C30: ProfesiÃ³n | D30: 11 | E30: 11 | F30: Bibliotecarios | G30: NULL | H30: 11 | I30: NULL | J30: 1 | K30: 1 | L30: admin | M30: 43606.789 | N30: NULL | O30: NULL
A31: 484 | B31: 003 | C31: ProfesiÃ³n | D31: 12 | E31: 12 | F31: BiÃ³logo | G31: NULL | H31: 12 | I31: NULL | J31: 1 | K31: 1 | L31: admin | M31: 43606.789 | N31: NULL | O31: NULL
... A131: 584 | B131: 003 | C131: ProfesiÃ³n | D131: 112 | E131: 112 | F131: Vigilante sin Uso de Arma | G131: NULL | H131: 112 | I131: NULL | J131: 1 | K131: 1 | L131: admin | M131: 43606.789 | N131: NULL | O131: NULL
A132: 585 | B132: 004 | C132: Actividad EconÃ³mica | D132: NULL | E132: NULL | F132: NULL | G132: NULL | H132: NULL | I132: NULL | J132: NULL | K132: 1 | L132: admin | M132: 43606.789 | N132: NULL | O132: NULL
A133: 586 | B133: 004 | C133: Actividad EconÃ³mica | D133: 1 | E133: 1 | F133: Acabado de productos textiles | G133: NULL | H133: 1712 | I133: NULL | J133: 1 | K133: 1 | L133: admin | M133: 43606.789 | N133: NULL | O133: NULL
A134: 587 | B134: 004 | C134: Actividad EconÃ³mica | D134: 2 | E134: 2 | F134: Acondicionamiento de edificios | G134: NULL | H134: 4530 | I134: NULL | J134: 1 | K134: 1 | L134: admin | M134: 43606.789 | N134: NULL | O134: NULL
A135: 588 | B135: 004 | C135: Actividad EconÃ³mica | D135: 3 | E135: 3 | F135: Actividades auxiliares de la financiaciÃ³n de planes de seguros y de pensiones | G135: NULL | H135: 6720 | I135: NULL | J135: 1 | K135: 1 | L135: admin | M135: 43606.789 | N135: NULL | O135: NULL
A136: 589 | B136: 004 | C136: Actividad EconÃ³mica | D136: 4 | E136: 4 | F136: Actividades auxiliares de la intermediaciÃ³n financiera n.c.p. | G136: NULL | H136: 6719 | I136: NULL | J136: 1 | K136: 1 | L136: admin | M136: 43606.789 | N136: NULL | O136: NULL
A137: 590 | B137: 004 | C137: Actividad EconÃ³mica | D137: 5 | E137: 5 | F137: Actividades bursÃ¡tiles | G137: NULL | H137: 6712 | I137: NULL | J137: 1 | K137: 1 | L137: admin | M137: 43606.789 | N137: NULL | O137: NULL
A138: 591 | B138: 004 | C138: Actividad EconÃ³mica | D138: 6 | E138: 6 | F138: Actividades de agencias de noticias | G138: NULL | H138: 9220 | I138: NULL | J138: 1 | K138: 1 | L138: admin | M138: 43606.789 | N138: NULL | O138: NULL
A139: 592 | B139: 004 | C139: Actividad EconÃ³mica | D139: 7 | E139: 7 | F139: Actividades de agencias de viajes y organizadores de viajes; actividades de asistencÃ­a a turistas n.c.p. | G139: NULL | H139: 6304 | I139: NULL | J139: 1 | K139: 1 | L139: admin | M139: 43606.789 | N139: NULL | O139: NULL
...

Sheet DATA_SOLICITUD
A1: @id_multitabla | B1: @codigo_tabla | C1: @nombre_tabla | D1: @codigo | E1: @orden | F1: @valor@ | G1: @valor_aux | H1: @valor_crm | I1: @valor_flex | J1: @estado@ | K1: @estado_tabla | L1: @usuario_crea | M1: @fecha_crea | N1: @usuario_modif | O1: @fecha_modif | P1: INSERT
A2: DEFAULT | B2: 010 | C2: Nacionalidad | D2: NULL | E2: NULL | F2: NULL | G2: NULL | H2: NULL | I2: NULL | J2: NULL | K2: 1 | L2: admin | M2: DEFAULT | N2: NULL | O2: NULL | P2: =SUBSTITUTE(SUBSTITUTE(SUBSTITUTE(SUBSTITUTE(SUBSTITUTE(SUBSTITUTE(SUBSTITUTE(SUBSTITUTE(SUBSTITUTE(SUBSTITUTE(SUBSTITUTE(INSERT!$B$3,DATA_SOLICITUD!$B$1,IF(B2="NULL",B2,CONCATENATE("'",B2,"'"))),DATA_SOLICITUD!$C$1,IF(C2="NULL",C2,CONCATENATE("'",C2,"'"))),DATA_SOLICITUD!$D$1,IF(D2="NULL",D2,CONCATENATE("'",D2,"'"))),DATA_SOLICITUD!$E$1,IF(E2="NULL",E2,CONCATENATE("'",E2,"'"))),DATA_SOLICITUD!$F$1,IF(F2="NULL",F2,CONCATENATE("'",F2,"'"))),DATA_SOLICITUD!$G$1,IF(G2="NULL",G2,CONCATENATE("'",G2,"'"))),DATA_SOLICITUD!$H$1,IF(H2="NULL",H2,CONCATENATE("'",H2,"'"))),DATA_SOLICITUD!$I$1,IF(I2="NULL",I2,CONCATENATE("'",I2,"'"))),DATA_SOLICITUD!$J$1,IF(J2="NULL",J2,CONCATENATE("'",J2,"'"))),DATA_SOLICITUD!$K$1,IF(K2="NULL",K2,CONCATENATE("'",K2,"'"))),DATA_SOLICITUD!$L$1,IF(L2="NULL",L2,CONCATENATE("'",L2,"'"))) -> INSERT INTO `multitabla` (`id_multitabla`, `codigo_tabla`, `nombre_tabla`, `codigo`, `orden`, `valor`, `valor_aux`, `valor_crm`, `estado`, `estado_tabla`, `usuario_crea`, `fecha_crea`, `usuario_modif`, `fecha_modif`) VALUES (DEFAULT, '010', 'Nacionalidad', NULL, NULL, NULL, NULL, NULL, NULL, '1', 'admin', DEFAULT, NULL, NULL);
A3: DEFAULT | B3: 010 | C3: Nacionalidad | D3: 1 | E3: 1 | F3: Afgano | G3: 1 | H3: 538560018 | I3: NULL | J3: 1 | K3: 1 | L3: admin | M3: DEFAULT | N3: NULL | O3: NULL | P3: =SUBSTITUTE(SUBSTITUTE(SUBSTITUTE(SUBSTITUTE(SUBSTITUTE(SUBSTITUTE(SUBSTITUTE(SUBSTITUTE(SUBSTITUTE(SUBSTITUTE(SUBSTITUTE(INSERT!$B$3,DATA_SOLICITUD!$B$1,IF(B3="NULL",B3,CONCATENATE("'",B3,"'"))),DATA_SOLICITUD!$C$1,IF(C3="NULL",C3,CONCATENATE("'",C3,"'"))),DATA_SOLICITUD!$D$1,IF(D3="NULL",D3,CONCATENATE("'",D3,"'"))),DATA_SOLICITUD!$E$1,IF(E3="NULL",E3,CONCATENATE("'",E3,"'"))),DATA_SOLICITUD!$F$1,IF(F3="NULL",F3,CONCATENATE("'",F3,"'"))),DATA_SOLICITUD!$G$1,IF(G3="NULL",G3,CONCATENATE("'",G3,"'"))),DATA_SOLICITUD!$H$1,IF(H3="NULL",H3,CONCATENATE("'",H3,"'"))),DATA_SOLICITUD!$I$1,IF(I3="NULL",I3,CONCATENATE("'",I3,"'"))),DATA_SOLICITUD!$J$1,IF(J3="NULL",J3,CONCATENATE("'",J3,"'"))),DATA_SOLICITUD!$K$1,IF(K3="NULL",K3,CONCATENATE("'",K3,"'"))),DATA_SOLICITUD!$L$1,IF(L3="NULL",L3,CONCATENATE("'",L3,"'"))) -> INSERT INTO `multitabla` (`id_multitabla`, `codigo_tabla`, `nombre_tabla`, `codigo`, `orden`, `valor`, `valor_aux`, `valor_crm`, `estado`, `estado_tabla`, `usuario_crea`, `fecha_crea`, `usuario_modif`, `fecha_modif`) VALUES (DEFAULT, '010', 'Nacionalidad', '1', '1', 'Afgano', '1', '538560018', '1', '1', 'admin', DEFAULT, NULL, NULL);
A4: DEFAULT | B4: 010 | C4: Nacionalidad | D4: 2 | E4: 2 | F4: Albanés | G4: 114 | H4: 538560019 | I4: NULL | J4: 1 | K4: 1 | L4: admin | M4: DEFAULT | N4: NULL | O4: NULL | P4: =SUBSTITUTE(SUBSTITUTE(SUBSTITUTE(SUBSTITUTE(SUBSTITUTE(SUBSTITUTE(SUBSTITUTE(SUBSTITUTE(SUBSTITUTE(SUBSTITUTE(SUBSTITUTE(INSERT!$B$3,DATA_SOLICITUD!$B$1,IF(B4="NULL",B4,CONCATENATE("'",B4,"'"))),DATA_SOLICITUD!$C$1,IF(C4="NULL",C4,CONCATENATE("'",C4,"'"))),DATA_SOLICITUD!$D$1,IF(D4="NULL",D4,CONCATENATE("'",D4,"'"))),DATA_SOLICITUD!$E$1,IF(E4="NULL",E4,CONCATENATE("'",E4,"'"))),DATA_SOLICITUD!$F$1,IF(F4="NULL",F4,CONCATENATE("'",F4,"'"))),DATA_SOLICITUD!$G$1,IF(G4="NULL",G4,CONCATENATE("'",G4,"'"))),DATA_SOLICITUD!$H$1,IF(H4="NULL",H4,CONCATENATE("'",H4,"'"))),DATA_SOLICITUD!$I$1,IF(I4="NULL",I4,CONCATENATE("'",I4,"'"))),DATA_SOLICITUD!$J$1,IF(J4="NULL",J4,CONCATENATE("'",J4,"'"))),DATA_SOLICITUD!$K$1,IF(K4="NULL",K4,CONCATENATE("'",K4,"'"))),DATA_SOLICITUD!$L$1,IF(L4="NULL",L4,CONCATENATE("'",L4,"'"))) -> INSERT INTO `multitabla` (`id_multitabla`, `codigo_tabla`, `nombre_tabla`, `codigo`, `orden`, `valor`, `valor_aux`, `valor_crm`, `estado`, `estado_tabla`, `usuario_crea`, `fecha_crea`, `usuario_modif`, `fecha_modif`) VALUES (DEFAULT, '010', 'Nacionalidad', '2', '2', 'Albanés', '114', '538560019', '1', '1', 'admin', DEFAULT, NULL, NULL);
A5: DEFAULT | B5: 010 | C5: Nacionalidad | D5: 3 | E5: 3 | F5: Alemán | G5: 2 | H5: 538560020 | I5: NULL | J5: 1 | K5: 1 | L5: admin | M5: DEFAULT | N5: NULL | O5: NULL | P5: =SUBSTITUTE(SUBSTITUTE(SUBSTITUTE(SUBSTITUTE(SUBSTITUTE(SUBSTITUTE(SUBSTITUTE(SUBSTITUTE(SUBSTITUTE(SUBSTITUTE(SUBSTITUTE(INSERT!$B$3,DATA_SOLICITUD!$B$1,IF(B5="NULL",B5,CONCATENATE("'",B5,"'"))),DATA_SOLICITUD!$C$1,IF(C5="NULL",C5,CONCATENATE("'",C5,"'"))),DATA_SOLICITUD!$D$1,IF(D5="NULL",D5,CONCATENATE("'",D5,"'"))),DATA_SOLICITUD!$E$1,IF(E5="NULL",E5,CONCATENATE("'",E5,"'"))),DATA_SOLICITUD!$F$1,IF(F5="NULL",F5,CONCATENATE("'",F5,"'"))),DATA_SOLICITUD!$G$1,IF(G5="NULL",G5,CONCATENATE("'",G5,"'"))),DATA_SOLICITUD!$H$1,IF(H5="NULL",H5,CONCATENATE("'",H5,"'"))),DATA_SOLICITUD!$I$1,IF(I5="NULL",I5,CONCATENATE("'",I5,"'"))),DATA_SOLICITUD!$J$1,IF(J5="NULL",J5,CONCATENATE("'",J5,"'"))),DATA_SOLICITUD!$K$1,IF(K5="NULL",K5,CONCATENATE("'",K5,"'"))),DATA_SOLICITUD!$L$1,IF(L5="NULL",L5,CONCATENATE("'",L5,"'"))) -> INSERT INTO `multitabla` (`id_multitabla`, `codigo_tabla`, `nombre_tabla`, `codigo`, `orden`, `valor`, `valor_aux`, `valor_crm`, `estado`, `estado_tabla`, `usuario_crea`, `fecha_crea`, `usuario_modif`, `fecha_modif`) VALUES (DEFAULT, '010', 'Nacionalidad', '3', '3', 'Alemán', '2', '538560020', '1', '1', 'admin', DEFAULT, NULL, NULL);
A6: DEFAULT | B6: 010 | C6: Nacionalidad | D6: 4 | E6: 4 | F6: Andorrana | G6: 96 | H6: 538560021 | I6: NULL | J6: 1 | K6: 1 | L6: admin | M6: DEFAULT | N6: NULL | O6: NULL | P6: =SUBSTITUTE(SUBSTITUTE(SUBSTITUTE(SUBSTITUTE(SUBSTITUTE(SUBSTITUTE(SUBSTITUTE(SUBSTITUTE(SUBSTITUTE(SUBSTITUTE(SUBSTITUTE(INSERT!$B$3,DATA_SOLICITUD!$B$1,IF(B6="NULL",B6,CONCATENATE("'",B6,"'"))),DATA_SOLICITUD!$C$1,IF(C6="NULL",C6,CONCATENATE("'",C6,"'"))),DATA_SOLICITUD!$D$1,IF(D6="NULL",D6,CONCATENATE("'",D6,"'"))),DATA_SOLICITUD!$E$1,IF(E6="NULL",E6,CONCATENATE("'",E6,"'"))),DATA_SOLICITUD!$F$1,IF(F6="NULL",F6,CONCATENATE("'",F6,"'"))),DATA_SOLICITUD!$G$1,IF(G6="NULL",G6,CONCATENATE("'",G6,"'"))),DATA_SOLICITUD!$H$1,IF(H6="NULL",H6,CONCATENATE("'",H6,"'"))),DATA_SOLICITUD!$I$1,IF(I6="NULL",I6,CONCATENATE("'",I6,"'"))),DATA_SOLICITUD!$J$1,IF(J6="NULL",J6,CONCATENATE("'",J6,"'"))),DATA_SOLICITUD!$K$1,IF(K6="NULL",K6,CONCATENATE("'",K6,"'"))),DATA_SOLICITUD!$L$1,IF(L6="NULL",L6,CONCATENATE("'",L6,"'"))) -> INSERT INTO `multitabla` (`id_multitabla`, `codigo_tabla`, `nombre_tabla`, `codigo`, `orden`, `valor`, `valor_aux`, `valor_crm`, `estado`, `estado_tabla`, `usuario_crea`, `fecha_crea`, `usuario_modif`, `fecha_modif`) VALUES (DEFAULT, '010', 'Nacionalidad', '4', '4', 'Andorrana', '96', '538560021', '1', '1', 'admin', DEFAULT, NULL, NULL);
A7: DEFAULT | B7: 010 | C7: Nacionalidad | D7: 5 | E7: 5 | F7: Anguilense | G7: 73 | H7: 538560022 | I7: NULL | J7: 1 | K7: 1 | L7: admin | M7: DEFAULT | N7: NULL | O7: NULL | P7: =SUBSTITUTE(SUBSTITUTE(SUBSTITUTE(SUBSTITUTE(SUBSTITUTE(SUBSTITUTE(SUBSTITUTE(SUBSTITUTE(SUBSTITUTE(SUBSTITUTE(SUBSTITUTE(INSERT!$B$3,DATA_SOLICITUD!$B$1,IF(B7="NULL",B7,CONCATENATE("'",B7,"'"))),DATA_SOLICITUD!$C$1,IF(C7="NULL",C7,CONCATENATE("'",C7,"'"))),DATA_SOLICITUD!$D$1,IF(D7="NULL",D7,CONCATENATE("'",D7,"'"))),DATA_SOLICITUD!$E$1,IF(E7="NULL",E7,CONCATENATE("'",E7,"'"))),DATA_SOLICITUD!$F$1,IF(F7="NULL",F7,CONCATENATE("'",F7,"'"))),DATA_SOLICITUD!$G$1,IF(G7="NULL",G7,CONCATENATE("'",G7,"'"))),DATA_SOLICITUD!$H$1,IF(H7="NULL",H7,CONCATENATE("'",H7,"'"))),DATA_SOLICITUD!$I$1,IF(I7="NULL",I7,CONCATENATE("'",I7,"'"))),DATA_SOLICITUD!$J$1,IF(J7="NULL",J7,CONCATENATE("'",J7,"'"))),DATA_SOLICITUD!$K$1,IF(K7="NULL",K7,CONCATENATE("'",K7,"'"))),DATA_SOLICITUD!$L$1,IF(L7="NULL",L7,CONCATENATE("'",L7,"'"))) -> INSERT INTO `multitabla` (`id_multitabla`, `codigo_tabla`, `nombre_tabla`, `codigo`, `orden`, `valor`, `valor_aux`, `valor_crm`, `estado`, `estado_tabla`, `usuario_crea`, `fecha_crea`, `usuario_modif`, `fecha_modif`) VALUES (DEFAULT, '010', 'Nacionalidad', '5', '5', 'Anguilense', '73', '538560022', '1', '1', 'admin', DEFAULT, NULL, NULL);
A8: DEFAULT | B8: 010 | C8: Nacionalidad | D8: 6 | E8: 6 | F8: Antiguana | G8: 74 | H8: 538560023 | I8: NULL | J8: 1 | K8: 1 | L8: admin | M8: DEFAULT | N8: NULL | O8: NULL | P8: =SUBSTITUTE(SUBSTITUTE(SUBSTITUTE(SUBSTITUTE(SUBSTITUTE(SUBSTITUTE(SUBSTITUTE(SUBSTITUTE(SUBSTITUTE(SUBSTITUTE(SUBSTITUTE(INSERT!$B$3,DATA_SOLICITUD!$B$1,IF(B8="NULL",B8,CONCATENATE("'",B8,"'"))),DATA_SOLICITUD!$C$1,IF(C8="NULL",C8,CONCATENATE("'",C8,"'"))),DATA_SOLICITUD!$D$1,IF(D8="NULL",D8,CONCATENATE("'",D8,"'"))),DATA_SOLICITUD!$E$1,IF(E8="NULL",E8,CONCATENATE("'",E8,"'"))),DATA_SOLICITUD!$F$1,IF(F8="NULL",F8,CONCATENATE("'",F8,"'"))),DATA_SOLICITUD!$G$1,IF(G8="NULL",G8,CONCATENATE("'",G8,"'"))),DATA_SOLICITUD!$H$1,IF(H8="NULL",H8,CONCATENATE("'",H8,"'"))),DATA_SOLICITUD!$I$1,IF(I8="NULL",I8,CONCATENATE("'",I8,"'"))),DATA_SOLICITUD!$J$1,IF(J8="NULL",J8,CONCATENATE("'",J8,"'"))),DATA_SOLICITUD!$K$1,IF(K8="NULL",K8,CONCATENATE("'",K8,"'"))),DATA_SOLICITUD!$L$1,IF(L8="NULL",L8,CONCATENATE("'",L8,"'"))) -> INSERT INTO `multitabla` (`id_multitabla`, `codigo_tabla`, `nombre_tabla`, `codigo`, `orden`, `valor`, `valor_aux`, `valor_crm`, `estado`, `estado_tabla`, `usuario_crea`, `fecha_crea`, `usuario_modif`, `fecha_modif`) VALUES (DEFAULT, '010', 'Nacionalidad', '6', '6', 'Antiguana', '74', '538560023', '1', '1', 'admin', DEFAULT, NULL, NULL);
A9: DEFAULT | B9: 010 | C9: Nacionalidad | D9: 7 | E9: 7 | F9: Árabe | G9: 3 | H9: 538560024 | I9: NULL | J9: 1 | K9: 1 | L9: admin | M9: DEFAULT | N9: NULL | O9: NULL | P9: =SUBSTITUTE(SUBSTITUTE(SUBSTITUTE(SUBSTITUTE(SUBSTITUTE(SUBSTITUTE(SUBSTITUTE(SUBSTITUTE(SUBSTITUTE(SUBSTITUTE(SUBSTITUTE(INSERT!$B$3,DATA_SOLICITUD!$B$1,IF(B9="NULL",B9,CONCATENATE("'",B9,"'"))),DATA_SOLICITUD!$C$1,IF(C9="NULL",C9,CONCATENATE("'",C9,"'"))),DATA_SOLICITUD!$D$1,IF(D9="NULL",D9,CONCATENATE("'",D9,"'"))),DATA_SOLICITUD!$E$1,IF(E9="NULL",E9,CONCATENATE("'",E9,"'"))),DATA_SOLICITUD!$F$1,IF(F9="NULL",F9,CONCATENATE("'",F9,"'"))),DATA_SOLICITUD!$G$1,IF(G9="NULL",G9,CONCATENATE("'",G9,"'"))),DATA_SOLICITUD!$H$1,IF(H9="NULL",H9,CONCATENATE("'",H9,"'"))),DATA_SOLICITUD!$I$1,IF(I9="NULL",I9,CONCATENATE("'",I9,"'"))),DATA_SOLICITUD!$J$1,IF(J9="NULL",J9,CONCATENATE("'",J9,"'"))),DATA_SOLICITUD!$K$1,IF(K9="NULL",K9,CONCATENATE("'",K9,"'"))),DATA_SOLICITUD!$L$1,IF(L9="NULL",L9,CONCATENATE("'",L9,"'"))) -> INSERT INTO `multitabla` (`id_multitabla`, `codigo_tabla`, `nombre_tabla`, `codigo`, `orden`, `valor`, `valor_aux`, `valor_crm`, `estado`, `estado_tabla`, `usuario_crea`, `fecha_crea`, `usuario_modif`, `fecha_modif`) VALUES (DEFAULT, '010', 'Nacionalidad', '7', '7', 'Árabe', '3', '538560024', '1', '1', 'admin', DEFAULT, NULL, NULL);
A10: DEFAULT | B10: 010 | C10: Nacionalidad | D10: 8 | E10: 8 | F10: Argentino | G10: 4 | H10: 538560001 | I10: NULL | J10: 1 | K10: 1 | L10: admin | M10: DEFAULT | N10: NULL | O10: NULL | P10: =SUBSTITUTE(SUBSTITUTE(SUBSTITUTE(SUBSTITUTE(SUBSTITUTE(SUBSTITUTE(SUBSTITUTE(SUBSTITUTE(SUBSTITUTE(SUBSTITUTE(SUBSTITUTE(INSERT!$B$3,DATA_SOLICITUD!$B$1,IF(B10="NULL",B10,CONCATENATE("'",B10,"'"))),DATA_SOLICITUD!$C$1,IF(C10="NULL",C10,CONCATENATE("'",C10,"'"))),DATA_SOLICITUD!$D$1,IF(D10="NULL",D10,CONCATENATE("'",D10,"'"))),DATA_SOLICITUD!$E$1,IF(E10="NULL",E10,CONCATENATE("'",E10,"'"))),DATA_SOLICITUD!$F$1,IF(F10="NULL",F10,CONCATENATE("'",F10,"'"))),DATA_SOLICITUD!$G$1,IF(G10="NULL",G10,CONCATENATE("'",G10,"'"))),DATA_SOLICITUD!$H$1,IF(H10="NULL",H10,CONCATENATE("'",H10,"'"))),DATA_SOLICITUD!$I$1,IF(I10="NULL",I10,CONCATENATE("'",I10,"'"))),DATA_SOLICITUD!$J$1,IF(J10="NULL",J10,CONCATENATE("'",J10,"'"))),DATA_SOLICITUD!$K$1,IF(K10="NULL",K10,CONCATENATE("'",K10,"'"))),DATA_SOLICITUD!$L$1,IF(L10="NULL",L10,CONCATENATE("'",L10,"'"))) -> INSERT INTO `multitabla` (`id_multitabla`, `codigo_tabla`, `nombre_tabla`, `codigo`, `orden`, `valor`, `valor_aux`, `valor_crm`, `estado`, `estado_tabla`, `usuario_crea`, `fecha_crea`, `usuario_modif`, `fecha_modif`) VALUES (DEFAULT, '010', 'Nacionalidad', '8', '8', 'Argentino', '4', '538560001', '1', '1', 'admin', DEFAULT, NULL, NULL);
A11: DEFAULT | B11: 010 | C11: Nacionalidad | D11: 9 | E11: 9 | F11: Arubana | G11: 75 | H11: 538560025 | I11: NULL | J11: 1 | K11: 1 | L11: admin | M11: DEFAULT | N11: NULL | O11: NULL | P11: =SUBSTITUTE(SUBSTITUTE(SUBSTITUTE(SUBSTITUTE(SUBSTITUTE(SUBSTITUTE(SUBSTITUTE(SUBSTITUTE(SUBSTITUTE(SUBSTITUTE(SUBSTITUTE(INSERT!$B$3,DATA_SOLICITUD!$B$1,IF(B11="NULL",B11,CONCATENATE("'",B11,"'"))),DATA_SOLICITUD!$C$1,IF(C11="NULL",C11,CONCATENATE("'",C11,"'"))),DATA_SOLICITUD!$D$1,IF(D11="NULL",D11,CONCATENATE("'",D11,"'"))),DATA_SOLICITUD!$E$1,IF(E11="NULL",E11,CONCATENATE("'",E11,"'"))),DATA_SOLICITUD!$F$1,IF(F11="NULL",F11,CONCATENATE("'",F11,"'"))),DATA_SOLICITUD!$G$1,IF(G11="NULL",G11,CONCATENATE("'",G11,"'"))),DATA_SOLICITUD!$H$1,IF(H11="NULL",H11,CONCATENATE("'",H11,"'"))),DATA_SOLICITUD!$I$1,IF(I11="NULL",I11,CONCATENATE("'",I11,"'"))),DATA_SOLICITUD!$J$1,IF(J11="NULL",J11,CONCATENATE("'",J11,"'"))),DATA_SOLICITUD!$K$1,IF(K11="NULL",K11,CONCATENATE("'",K11,"'"))),DATA_SOLICITUD!$L$1,IF(L11="NULL",L11,CONCATENATE("'",L11,"'"))) -> INSERT INTO `multitabla` (`id_multitabla`, `codigo_tabla`, `nombre_tabla`, `codigo`, `orden`, `valor`, `valor_aux`, `valor_crm`, `estado`, `estado_tabla`, `usuario_crea`, `fecha_crea`, `usuario_modif`, `fecha_modif`) VALUES (DEFAULT, '010', 'Nacionalidad', '9', '9', 'Arubana', '75', '538560025', '1', '1', 'admin', DEFAULT, NULL, NULL);
A12: DEFAULT | B12: 010 | C12: Nacionalidad | D12: 10 | E12: 10 | F12: Australiano | G12: 5 | H12: 538560015 | I12: NULL | J12: 1 | K12: 1 | L12: admin | M12: DEFAULT | N12: NULL | O12: NULL | P12: =SUBSTITUTE(SUBSTITUTE(SUBSTITUTE(SUBSTITUTE(SUBSTITUTE(SUBSTITUTE(SUBSTITUTE(SUBSTITUTE(SUBSTITUTE(SUBSTITUTE(SUBSTITUTE(INSERT!$B$3,DATA_SOLICITUD!$B$1,IF(B12="NULL",B12,CONCATENATE("'",B12,"'"))),DATA_SOLICITUD!$C$1,IF(C12="NULL",C12,CONCATENATE("'",C12,"'"))),DATA_SOLICITUD!$D$1,IF(D12="NULL",D12,CONCATENATE("'",D12,"'"))),DATA_SOLICITUD!$E$1,IF(E12="NULL",E12,CONCATENATE("'",E12,"'"))),DATA_SOLICITUD!$F$1,IF(F12="NULL",F12,CONCATENATE("'",F12,"'"))),DATA_SOLICITUD!$G$1,IF(G12="NULL",G12,CONCATENATE("'",G12,"'"))),DATA_SOLICITUD!$H$1,IF(H12="NULL",H12,CONCATENATE("'",H12,"'"))),DATA_SOLICITUD!$I$1,IF(I12="NULL",I12,CONCATENATE("'",I12,"'"))),DATA_SOLICITUD!$J$1,IF(J12="NULL",J12,CONCATENATE("'",J12,"'"))),DATA_SOLICITUD!$K$1,IF(K12="NULL",K12,CONCATENATE("'",K12,"'"))),DATA_SOLICITUD!$L$1,IF(L12="NULL",L12,CONCATENATE("'",L12,"'"))) -> INSERT INTO `multitabla` (`id_multitabla`, `codigo_tabla`, `nombre_tabla`, `codigo`, `orden`, `valor`, `valor_aux`, `valor_crm`, `estado`, `estado_tabla`, `usuario_crea`, `fecha_crea`, `usuario_modif`, `fecha_modif`) VALUES (DEFAULT, '010', 'Nacionalidad', '10', '10', 'Australiano', '5', '538560015', '1', '1', 'admin', DEFAULT, NULL, NULL);
A13: DEFAULT | B13: 010 | C13: Nacionalidad | D13: 11 | E13: 11 | F13: Bahameña | G13: 94 | H13: 538560026 | I13: NULL | J13: 1 | K13: 1 | L13: admin | M13: DEFAULT | N13: NULL | O13: NULL | P13: =SUBSTITUTE(SUBSTITUTE(SUBSTITUTE(SUBSTITUTE(SUBSTITUTE(SUBSTITUTE(SUBSTITUTE(SUBSTITUTE(SUBSTITUTE(SUBSTITUTE(SUBSTITUTE(INSERT!$B$3,DATA_SOLICITUD!$B$1,IF(B13="NULL",B13,CONCATENATE("'",B13,"'"))),DATA_SOLICITUD!$C$1,IF(C13="NULL",C13,CONCATENATE("'",C13,"'"))),DATA_SOLICITUD!$D$1,IF(D13="NULL",D13,CONCATENATE("'",D13,"'"))),DATA_SOLICITUD!$E$1,IF(E13="NULL",E13,CONCATENATE("'",E13,"'"))),DATA_SOLICITUD!$F$1,IF(F13="NULL",F13,CONCATENATE("'",F13,"'"))),DATA_SOLICITUD!$G$1,IF(G13="NULL",G13,CONCATENATE("'",G13,"'"))),DATA_SOLICITUD!$H$1,IF(H13="NULL",H13,CONCATENATE("'",H13,"'"))),DATA_SOLICITUD!$I$1,IF(I13="NULL",I13,CONCATENATE("'",I13,"'"))),DATA_SOLICITUD!$J$1,IF(J13="NULL",J13,CONCATENATE("'",J13,"'"))),DATA_SOLICITUD!$K$1,IF(K13="NULL",K13,CONCATENATE("'",K13,"'"))),DATA_SOLICITUD!$L$1,IF(L13="NULL",L13,CONCATENATE("'",L13,"'"))) -> INSERT INTO `multitabla` (`id_multitabla`, `codigo_tabla`, `nombre_tabla`, `codigo`, `orden`, `valor`, `valor_aux`, `valor_crm`, `estado`, `estado_tabla`, `usuario_crea`, `fecha_crea`, `usuario_modif`, `fecha_modif`) VALUES (DEFAULT, '010', 'Nacionalidad', '11', '11', 'Bahameña', '94', '538560026', '1', '1', 'admin', DEFAULT, NULL, NULL);
A14: DEFAULT | B14: 010 | C14: Nacionalidad | D14: 12 | E14: 12 | F14: Barbadense | G14: 77 | H14: 538560027 | I14: NULL | J14: 1 | K14: 1 | L14: admin | M14: DEFAULT | N14: NULL | O14: NULL | P14: =SUBSTITUTE(SUBSTITUTE(SUBSTITUTE(SUBSTITUTE(SUBSTITUTE(SUBSTITUTE(SUBSTITUTE(SUBSTITUTE(SUBSTITUTE(SUBSTITUTE(SUBSTITUTE(INSERT!$B$3,DATA_SOLICITUD!$B$1,IF(B14="NULL",B14,CONCATENATE("'",B14,"'"))),DATA_SOLICITUD!$C$1,IF(C14="NULL",C14,CONCATENATE("'",C14,"'"))),DATA_SOLICITUD!$D$1,IF(D14="NULL",D14,CONCATENATE("'",D14,"'"))),DATA_SOLICITUD!$E$1,IF(E14="NULL",E14,CONCATENATE("'",E14,"'"))),DATA_SOLICITUD!$F$1,IF(F14="NULL",F14,CONCATENATE("'",F14,"'"))),DATA_SOLICITUD!$G$1,IF(G14="NULL",G14,CONCATENATE("'",G14,"'"))),DATA_SOLICITUD!$H$1,IF(H14="NULL",H14,CONCATENATE("'",H14,"'"))),DATA_SOLICITUD!$I$1,IF(I14="NULL",I14,CONCATENATE("'",I14,"'"))),DATA_SOLICITUD!$J$1,IF(J14="NULL",J14,CONCATENATE("'",J14,"'"))),DATA_SOLICITUD!$K$1,IF(K14="NULL",K14,CONCATENATE("'",K14,"'"))),DATA_SOLICITUD!$L$1,IF(L14="NULL",L14,CONCATENATE("'",L14,"'"))) -> INSERT INTO `multitabla` (`id_multitabla`, `codigo_tabla`, `nombre_tabla`, `codigo`, `orden`, `valor`, `valor_aux`, `valor_crm`, `estado`, `estado_tabla`, `usuario_crea`, `fecha_crea`, `usuario_modif`, `fecha_modif`) VALUES (DEFAULT, '010', 'Nacionalidad', '12', '12', 'Barbadense', '77', '538560027', '1', '1', 'admin', DEFAULT, NULL, NULL);
... A83: DEFAULT | B83: 010 | C83: Nacionalidad | D83: 81 | E83: 81 | F83: Montserratense | G83: 89 | H83: 538560094 | I83: NULL | J83: 1 | K83: 1 | L83: admin | M83: DEFAULT | N83: NULL | O83: NULL | P83: =SUBSTITUTE(SUBSTITUTE(SUBSTITUTE(SUBSTITUTE(SUBSTITUTE(SUBSTITUTE(SUBSTITUTE(SUBSTITUTE(SUBSTITUTE(SUBSTITUTE(SUBSTITUTE(INSERT!$B$3,DATA_SOLICITUD!$B$1,IF(B83="NULL",B83,CONCATENATE("'",B83,"'"))),DATA_SOLICITUD!$C$1,IF(C83="NULL",C83,CONCATENATE("'",C83,"'"))),DATA_SOLICITUD!$D$1,IF(D83="NULL",D83,CONCATENATE("'",D83,"'"))),DATA_SOLICITUD!$E$1,IF(E83="NULL",E83,CONCATENATE("'",E83,"'"))),DATA_SOLICITUD!$F$1,IF(F83="NULL",F83,CONCATENATE("'",F83,"'"))),DATA_SOLICITUD!$G$1,IF(G83="NULL",G83,CONCATENATE("'",G83,"'"))),DATA_SOLICITUD!$H$1,IF(H83="NULL",H83,CONCATENATE("'",H83,"'"))),DATA_SOLICITUD!$I$1,IF(I83="NULL",I83,CONCATENATE("'",I83,"'"))),DATA_SOLICITUD!$J$1,IF(J83="NULL",J83,CONCATENATE("'",J83,"'"))),DATA_SOLICITUD!$K$1,IF(K83="NULL",K83,CONCATENATE("'",K83,"'"))),DATA_SOLICITUD!$L$1,IF(L83="NULL",L83,CONCATENATE("'",L83,"'"))) -> INSERT INTO `multitabla` (`id_multitabla`, `codigo_tabla`, `nombre_tabla`, `codigo`, `orden`, `valor`, `valor_aux`, `valor_crm`, `estado`, `estado_tabla`, `usuario_crea`, `fecha_crea`, `usuario_modif`, `fecha_modif`) VALUES (DEFAULT, '010', 'Nacionalidad', '81', '81', 'Montserratense', '89', '538560094', '1', '1', 'admin', DEFAULT, NULL, NULL);
A84: DEFAULT | B84: 010 | C84: Nacionalidad | D84: 82 | E84: 82 | F84: NACIONALIDAD DESCONOCIDA | G84: NULL | H84: 538560017 | I84: NULL | J84: 1 | K84: 1 | L84: admin | M84: DEFAULT | N84: NULL | O84: NULL | P84: =SUBSTITUTE(SUBSTITUTE(SUBSTITUTE(SUBSTITUTE(SUBSTITUTE(SUBSTITUTE(SUBSTITUTE(SUBSTITUTE(SUBSTITUTE(SUBSTITUTE(SUBSTITUTE(INSERT!$B$3,DATA_SOLICITUD!$B$1,IF(B84="NULL",B84,CONCATENATE("'",B84,"'"))),DATA_SOLICITUD!$C$1,IF(C84="NULL",C84,CONCATENATE("'",C84,"'"))),DATA_SOLICITUD!$D$1,IF(D84="NULL",D84,CONCATENATE("'",D84,"'"))),DATA_SOLICITUD!$E$1,IF(E84="NULL",E84,CONCATENATE("'",E84,"'"))),DATA_SOLICITUD!$F$1,IF(F84="NULL",F84,CONCATENATE("'",F84,"'"))),DATA_SOLICITUD!$G$1,IF(G84="NULL",G84,CONCATENATE("'",G84,"'"))),DATA_SOLICITUD!$H$1,IF(H84="NULL",H84,CONCATENATE("'",H84,"'"))),DATA_SOLICITUD!$I$1,IF(I84="NULL",I84,CONCATENATE("'",I84,"'"))),DATA_SOLICITUD!$J$1,IF(J84="NULL",J84,CONCATENATE("'",J84,"'"))),DATA_SOLICITUD!$K$1,IF(K84="NULL",K84,CONCATENATE("'",K84,"'"))),DATA_SOLICITUD!$L$1,IF(L84="NULL",L84,CONCATENATE("'",L84,"'"))) -> INSERT INTO `multitabla` (`id_multitabla`, `codigo_tabla`, `nombre_tabla`, `codigo`, `orden`, `valor`, `valor_aux`, `valor_crm`, `estado`, `estado_tabla`, `usuario_crea`, `fecha_crea`, `usuario_modif`, `fecha_modif`) VALUES (DEFAULT, '010', 'Nacionalidad', '82', '82', 'NACIONALIDAD DESCONOCIDA', NULL, '538560017', '1', '1', 'admin', DEFAULT, NULL, NULL);
A85: DEFAULT | B85: 010 | C85: Nacionalidad | D85: 83 | E85: 83 | F85: Nauruano | G85: 106 | H85: 538560095 | I85: NULL | J85: 1 | K85: 1 | L85: admin | M85: DEFAULT | N85: NULL | O85: NULL | P85: =SUBSTITUTE(SUBSTITUTE(SUBSTITUTE(SUBSTITUTE(SUBSTITUTE(SUBSTITUTE(SUBSTITUTE(SUBSTITUTE(SUBSTITUTE(SUBSTITUTE(SUBSTITUTE(INSERT!$B$3,DATA_SOLICITUD!$B$1,IF(B85="NULL",B85,CONCATENATE("'",B85,"'"))),DATA_SOLICITUD!$C$1,IF(C85="NULL",C85,CONCATENATE("'",C85,"'"))),DATA_SOLICITUD!$D$1,IF(D85="NULL",D85,CONCATENATE("'",D85,"'"))),DATA_SOLICITUD!$E$1,IF(E85="NULL",E85,CONCATENATE("'",E85,"'"))),DATA_SOLICITUD!$F$1,IF(F85="NULL",F85,CONCATENATE("'",F85,"'"))),DATA_SOLICITUD!$G$1,IF(G85="NULL",G85,CONCATENATE("'",G85,"'"))),DATA_SOLICITUD!$H$1,IF(H85="NULL",H85,CONCATENATE("'",H85,"'"))),DATA_SOLICITUD!$I$1,IF(I85="NULL",I85,CONCATENATE("'",I85,"'"))),DATA_SOLICITUD!$J$1,IF(J85="NULL",J85,CONCATENATE("'",J85,"'"))),DATA_SOLICITUD!$K$1,IF(K85="NULL",K85,CONCATENATE("'",K85,"'"))),DATA_SOLICITUD!$L$1,IF(L85="NULL",L85,CONCATENATE("'",L85,"'"))) -> INSERT INTO `multitabla` (`id_multitabla`, `codigo_tabla`, `nombre_tabla`, `codigo`, `orden`, `valor`, `valor_aux`, `valor_crm`, `estado`, `estado_tabla`, `usuario_crea`, `fecha_crea`, `usuario_modif`, `fecha_modif`) VALUES (DEFAULT, '010', 'Nacionalidad', '83', '83', 'Nauruano', '106', '538560095', '1', '1', 'admin', DEFAULT, NULL, NULL);
A86: DEFAULT | B86: 010 | C86: Nacionalidad | D86: 84 | E86: 84 | F86: Neocelandés | G86: 52 | H86: 538560096 | I86: NULL | J86: 1 | K86: 1 | L86: admin | M86: DEFAULT | N86: NULL | O86: NULL | P86: =SUBSTITUTE(SUBSTITUTE(SUBSTITUTE(SUBSTITUTE(SUBSTITUTE(SUBSTITUTE(SUBSTITUTE(SUBSTITUTE(SUBSTITUTE(SUBSTITUTE(SUBSTITUTE(INSERT!$B$3,DATA_SOLICITUD!$B$1,IF(B86="NULL",B86,CONCATENATE("'",B86,"'"))),DATA_SOLICITUD!$C$1,IF(C86="NULL",C86,CONCATENATE("'",C86,"'"))),DATA_SOLICITUD!$D$1,IF(D86="NULL",D86,CONCATENATE("'",D86,"'"))),DATA_SOLICITUD!$E$1,IF(E86="NULL",E86,CONCATENATE("'",E86,"'"))),DATA_SOLICITUD!$F$1,IF(F86="NULL",F86,CONCATENATE("'",F86,"'"))),DATA_SOLICITUD!$G$1,IF(G86="NULL",G86,CONCATENATE("'",G86,"'"))),DATA_SOLICITUD!$H$1,IF(H86="NULL",H86,CONCATENATE("'",H86,"'"))),DATA_SOLICITUD!$I$1,IF(I86="NULL",I86,CONCATENATE("'",I86,"'"))),DATA_SOLICITUD!$J$1,IF(J86="NULL",J86,CONCATENATE("'",J86,"'"))),DATA_SOLICITUD!$K$1,IF(K86="NULL",K86,CONCATENATE("'",K86,"'"))),DATA_SOLICITUD!$L$1,IF(L86="NULL",L86,CONCATENATE("'",L86,"'"))) -> INSERT INTO `multitabla` (`id_multitabla`, `codigo_tabla`, `nombre_tabla`, `codigo`, `orden`, `valor`, `valor_aux`, `valor_crm`, `estado`, `estado_tabla`, `usuario_crea`, `fecha_crea`, `usuario_modif`, `fecha_modif`) VALUES (DEFAULT, '010', 'Nacionalidad', '84', '84', 'Neocelandés', '52', '538560096', '1', '1', 'admin', DEFAULT, NULL, NULL);
A87: DEFAULT | B87: 010 | C87: Nacionalidad | D87: 85 | E87: 85 | F87: Nicaragüense | G87: 50 | H87: 538560098 | I87: NULL | J87: 1 | K87: 1 | L87: admin | M87: DEFAULT | N87: NULL | O87: NULL | P87: =SUBSTITUTE(SUBSTITUTE(SUBSTITUTE(SUBSTITUTE(SUBSTITUTE(SUBSTITUTE(SUBSTITUTE(SUBSTITUTE(SUBSTITUTE(SUBSTITUTE(SUBSTITUTE(INSERT!$B$3,DATA_SOLICITUD!$B$1,IF(B87="NULL",B87,CONCATENATE("'",B87,"'"))),DATA_SOLICITUD!$C$1,IF(C87="NULL",C87,CONCATENATE("'",C87,"'"))),DATA_SOLICITUD!$D$1,IF(D87="NULL",D87,CONCATENATE("'",D87,"'"))),DATA_SOLICITUD!$E$1,IF(E87="NULL",E87,CONCATENATE("'",E87,"'"))),DATA_SOLICITUD!$F$1,IF(F87="NULL",F87,CONCATENATE("'",F87,"'"))),DATA_SOLICITUD!$G$1,IF(G87="NULL",G87,CONCATENATE("'",G87,"'"))),DATA_SOLICITUD!$H$1,IF(H87="NULL",H87,CONCATENATE("'",H87,"'"))),DATA_SOLICITUD!$I$1,IF(I87="NULL",I87,CONCATENATE("'",I87,"'"))),DATA_SOLICITUD!$J$1,IF(J87="NULL",J87,CONCATENATE("'",J87,"'"))),DATA_SOLICITUD!$K$1,IF(K87="NULL",K87,CONCATENATE("'",K87,"'"))),DATA_SOLICITUD!$L$1,IF(L87="NULL",L87,CONCATENATE("'",L87,"'"))) -> INSERT INTO `multitabla` (`id_multitabla`, `codigo_tabla`, `nombre_tabla`, `codigo`, `orden`, `valor`, `valor_aux`, `valor_crm`, `estado`, `estado_tabla`, `usuario_crea`, `fecha_crea`, `usuario_modif`, `fecha_modif`) VALUES (DEFAULT, '010', 'Nacionalidad', '85', '85', 'Nicaragüense', '50', '538560098', '1', '1', 'admin', DEFAULT, NULL, NULL);
A88: DEFAULT | B88: 010 | C88: Nacionalidad | D88: 86 | E88: 86 | F88: Ninhuana | G88: 95 | H88: 538560099 | I88: NULL | J88: 1 | K88: 1 | L88: admin | M88: DEFAULT | N88: NULL | O88: NULL | P88: =SUBSTITUTE(SUBSTITUTE(SUBSTITUTE(SUBSTITUTE(SUBSTITUTE(SUBSTITUTE(SUBSTITUTE(SUBSTITUTE(SUBSTITUTE(SUBSTITUTE(SUBSTITUTE(INSERT!$B$3,DATA_SOLICITUD!$B$1,IF(B88="NULL",B88,CONCATENATE("'",B88,"'"))),DATA_SOLICITUD!$C$1,IF(C88="NULL",C88,CONCATENATE("'",C88,"'"))),DATA_SOLICITUD!$D$1,IF(D88="NULL",D88,CONCATENATE("'",D88,"'"))),DATA_SOLICITUD!$E$1,IF(E88="NULL",E88,CONCATENATE("'",E88,"'"))),DATA_SOLICITUD!$F$1,IF(F88="NULL",F88,CONCATENATE("'",F88,"'"))),DATA_SOLICITUD!$G$1,IF(G88="NULL",G88,CONCATENATE("'",G88,"'"))),DATA_SOLICITUD!$H$1,IF(H88="NULL",H88,CONCATENATE("'",H88,"'"))),DATA_SOLICITUD!$I$1,IF(I88="NULL",I88,CONCATENATE("'",I88,"'"))),DATA_SOLICITUD!$J$1,IF(J88="NULL",J88,CONCATENATE("'",J88,"'"))),DATA_SOLICITUD!$K$1,IF(K88="NULL",K88,CONCATENATE("'",K88,"'"))),DATA_SOLICITUD!$L$1,IF(L88="NULL",L88,CONCATENATE("'",L88,"'"))) -> INSERT INTO `multitabla` (`id_multitabla`, `codigo_tabla`, `nombre_tabla`, `codigo`, `orden`, `valor`, `valor_aux`, `valor_crm`, `estado`, `estado_tabla`, `usuario_crea`, `fecha_crea`, `usuario_modif`, `fecha_modif`) VALUES (DEFAULT, '010', 'Nacionalidad', '86', '86', 'Ninhuana', '95', '538560099', '1', '1', 'admin', DEFAULT, NULL, NULL);
A89: DEFAULT | B89: 010 | C89: Nacionalidad | D89: 87 | E89: 87 | F89: No identificada | G89: 71 | H89: 538560100 | I89: NULL | J89: 1 | K89: 1 | L89: admin | M89: DEFAULT | N89: NULL | O89: NULL | P89: =SUBSTITUTE(SUBSTITUTE(SUBSTITUTE(SUBSTITUTE(SUBSTITUTE(SUBSTITUTE(SUBSTITUTE(SUBSTITUTE(SUBSTITUTE(SUBSTITUTE(SUBSTITUTE(INSERT!$B$3,DATA_SOLICITUD!$B$1,IF(B89="NULL",B89,CONCATENATE("'",B89,"'"))),DATA_SOLICITUD!$C$1,IF(C89="NULL",C89,CONCATENATE("'",C89,"'"))),DATA_SOLICITUD!$D$1,IF(D89="NULL",D89,CONCATENATE("'",D89,"'"))),DATA_SOLICITUD!$E$1,IF(E89="NULL",E89,CONCATENATE("'",E89,"'"))),DATA_SOLICITUD!$F$1,IF(F89="NULL",F89,CONCATENATE("'",F89,"'"))),DATA_SOLICITUD!$G$1,IF(G89="NULL",G89,CONCATENATE("'",G89,"'"))),DATA_SOLICITUD!$H$1,IF(H89="NULL",H89,CONCATENATE("'",H89,"'"))),DATA_SOLICITUD!$I$1,IF(I89="NULL",I89,CONCATENATE("'",I89,"'"))),DATA_SOLICITUD!$J$1,IF(J89="NULL",J89,CONCATENATE("'",J89,"'"))),DATA_SOLICITUD!$K$1,IF(K89="NULL",K89,CONCATENATE("'",K89,"'"))),DATA_SOLICITUD!$L$1,IF(L89="NULL",L89,CONCATENATE("'",L89,"'"))) -> INSERT INTO `multitabla` (`id_multitabla`, `codigo_tabla`, `nombre_tabla`, `codigo`, `orden`, `valor`, `valor_aux`, `valor_crm`, `estado`, `estado_tabla`, `usuario_crea`, `fecha_crea`, `usuario_modif`, `fecha_modif`) VALUES (DEFAULT, '010', 'Nacionalidad', '87', '87', 'No identificada', '71', '538560100', '1', '1', 'admin', DEFAULT, NULL, NULL);
A90: DEFAULT | B90: 010 | C90: Nacionalidad | D90: 88 | E90: 88 | F90: Noruego | G90: 51 | H90: 538560101 | I90: NULL | J90: 1 | K90: 1 | L90: admin | M90: DEFAULT | N90: NULL | O90: NULL | P90: =SUBSTITUTE(SUBSTITUTE(SUBSTITUTE(SUBSTITUTE(SUBSTITUTE(SUBSTITUTE(SUBSTITUTE(SUBSTITUTE(SUBSTITUTE(SUBSTITUTE(SUBSTITUTE(INSERT!$B$3,DATA_SOLICITUD!$B$1,IF(B90="NULL",B90,CONCATENATE("'",B90,"'"))),DATA_SOLICITUD!$C$1,IF(C90="NULL",C90,CONCATENATE("'",C90,"'"))),DATA_SOLICITUD!$D$1,IF(D90="NULL",D90,CONCATENATE("'",D90,"'"))),DATA_SOLICITUD!$E$1,IF(E90="NULL",E90,CONCATENATE("'",E90,"'"))),DATA_SOLICITUD!$F$1,IF(F90="NULL",F90,CONCATENATE("'",F90,"'"))),DATA_SOLICITUD!$G$1,IF(G90="NULL",G90,CONCATENATE("'",G90,"'"))),DATA_SOLICITUD!$H$1,IF(H90="NULL",H90,CONCATENATE("'",H90,"'"))),DATA_SOLICITUD!$I$1,IF(I90="NULL",I90,CONCATENATE("'",I90,"'"))),DATA_SOLICITUD!$J$1,IF(J90="NULL",J90,CONCATENATE("'",J90,"'"))),DATA_SOLICITUD!$K$1,IF(K90="NULL",K90,CONCATENATE("'",K90,"'"))),DATA_SOLICITUD!$L$1,IF(L90="NULL",L90,CONCATENATE("'",L90,"'"))) -> INSERT INTO `multitabla` (`id_multitabla`, `codigo_tabla`, `nombre_tabla`, `codigo`, `orden`, `valor`, `valor_aux`, `valor_crm`, `estado`, `estado_tabla`, `usuario_crea`, `fecha_crea`, `usuario_modif`, `fecha_modif`) VALUES (DEFAULT, '010', 'Nacionalidad', '88', '88', 'Noruego', '51', '538560101', '1', '1', 'admin', DEFAULT, NULL, NULL);
A91: DEFAULT | B91: 010 | C91: Nacionalidad | D91: 89 | E91: 89 | F91: OTRA NACIONALIDAD | G91: NULL | H91: 538560016 | I91: NULL | J91: 1 | K91: 1 | L91: admin | M91: DEFAULT | N91: NULL | O91: NULL | P91: =SUBSTITUTE(SUBSTITUTE(SUBSTITUTE(SUBSTITUTE(SUBSTITUTE(SUBSTITUTE(SUBSTITUTE(SUBSTITUTE(SUBSTITUTE(SUBSTITUTE(SUBSTITUTE(INSERT!$B$3,DATA_SOLICITUD!$B$1,IF(B91="NULL",B91,CONCATENATE("'",B91,"'"))),DATA_SOLICITUD!$C$1,IF(C91="NULL",C91,CONCATENATE("'",C91,"'"))),DATA_SOLICITUD!$D$1,IF(D91="NULL",D91,CONCATENATE("'",D91,"'"))),DATA_SOLICITUD!$E$1,IF(E91="NULL",E91,CONCATENATE("'",E91,"'"))),DATA_SOLICITUD!$F$1,IF(F91="NULL",F91,CONCATENATE("'",F91,"'"))),DATA_SOLICITUD!$G$1,IF(G91="NULL",G91,CONCATENATE("'",G91,"'"))),DATA_SOLICITUD!$H$1,IF(H91="NULL",H91,CONCATENATE("'",H91,"'"))),DATA_SOLICITUD!$I$1,IF(I91="NULL",I91,CONCATENATE("'",I91,"'"))),DATA_SOLICITUD!$J$1,IF(J91="NULL",J91,CONCATENATE("'",J91,"'"))),DATA_SOLICITUD!$K$1,IF(K91="NULL",K91,CONCATENATE("'",K91,"'"))),DATA_SOLICITUD!$L$1,IF(L91="NULL",L91,CONCATENATE("'",L91,"'"))) -> INSERT INTO `multitabla` (`id_multitabla`, `codigo_tabla`, `nombre_tabla`, `codigo`, `orden`, `valor`, `valor_aux`, `valor_crm`, `estado`, `estado_tabla`, `usuario_crea`, `fecha_crea`, `usuario_modif`, `fecha_modif`) VALUES (DEFAULT, '010', 'Nacionalidad', '89', '89', 'OTRA NACIONALIDAD', NULL, '538560016', '1', '1', 'admin', DEFAULT, NULL, NULL);
A92: DEFAULT | B92: 010 | C92: Nacionalidad | D92: 90 | E92: 90 | F92: Panameño | G92: 53 | H92: 538560014 | I92: NULL | J92: 1 | K92: 1 | L92: admin | M92: DEFAULT | N92: NULL | O92: NULL | P92: =SUBSTITUTE(SUBSTITUTE(SUBSTITUTE(SUBSTITUTE(SUBSTITUTE(SUBSTITUTE(SUBSTITUTE(SUBSTITUTE(SUBSTITUTE(SUBSTITUTE(SUBSTITUTE(INSERT!$B$3,DATA_SOLICITUD!$B$1,IF(B92="NULL",B92,CONCATENATE("'",B92,"'"))),DATA_SOLICITUD!$C$1,IF(C92="NULL",C92,CONCATENATE("'",C92,"'"))),DATA_SOLICITUD!$D$1,IF(D92="NULL",D92,CONCATENATE("'",D92,"'"))),DATA_SOLICITUD!$E$1,IF(E92="NULL",E92,CONCATENATE("'",E92,"'"))),DATA_SOLICITUD!$F$1,IF(F92="NULL",F92,CONCATENATE("'",F92,"'"))),DATA_SOLICITUD!$G$1,IF(G92="NULL",G92,CONCATENATE("'",G92,"'"))),DATA_SOLICITUD!$H$1,IF(H92="NULL",H92,CONCATENATE("'",H92,"'"))),DATA_SOLICITUD!$I$1,IF(I92="NULL",I92,CONCATENATE("'",I92,"'"))),DATA_SOLICITUD!$J$1,IF(J92="NULL",J92,CONCATENATE("'",J92,"'"))),DATA_SOLICITUD!$K$1,IF(K92="NULL",K92,CONCATENATE("'",K92,"'"))),DATA_SOLICITUD!$L$1,IF(L92="NULL",L92,CONCATENATE("'",L92,"'"))) -> INSERT INTO `multitabla` (`id_multitabla`, `codigo_tabla`, `nombre_tabla`, `codigo`, `orden`, `valor`, `valor_aux`, `valor_crm`, `estado`, `estado_tabla`, `usuario_crea`, `fecha_crea`, `usuario_modif`, `fecha_modif`) VALUES (DEFAULT, '010', 'Nacionalidad', '90', '90', 'Panameño', '53', '538560014', '1', '1', 'admin', DEFAULT, NULL, NULL);
A93: DEFAULT | B93: 010 | C93: Nacionalidad | D93: 91 | E93: 91 | F93: Paraguayo | G93: 54 | H93: 538560012 | I93: NULL | J93: 1 | K93: 1 | L93: admin | M93: DEFAULT | N93: NULL | O93: NULL | P93: =SUBSTITUTE(SUBSTITUTE(SUBSTITUTE(SUBSTITUTE(SUBSTITUTE(SUBSTITUTE(SUBSTITUTE(SUBSTITUTE(SUBSTITUTE(SUBSTITUTE(SUBSTITUTE(INSERT!$B$3,DATA_SOLICITUD!$B$1,IF(B93="NULL",B93,CONCATENATE("'",B93,"'"))),DATA_SOLICITUD!$C$1,IF(C93="NULL",C93,CONCATENATE("'",C93,"'"))),DATA_SOLICITUD!$D$1,IF(D93="NULL",D93,CONCATENATE("'",D93,"'"))),DATA_SOLICITUD!$E$1,IF(E93="NULL",E93,CONCATENATE("'",E93,"'"))),DATA_SOLICITUD!$F$1,IF(F93="NULL",F93,CONCATENATE("'",F93,"'"))),DATA_SOLICITUD!$G$1,IF(G93="NULL",G93,CONCATENATE("'",G93,"'"))),DATA_SOLICITUD!$H$1,IF(H93="NULL",H93,CONCATENATE("'",H93,"'"))),DATA_SOLICITUD!$I$1,IF(I93="NULL",I93,CONCATENATE("'",I93,"'"))),DATA_SOLICITUD!$J$1,IF(J93="NULL",J93,CONCATENATE("'",J93,"'"))),DATA_SOLICITUD!$K$1,IF(K93="NULL",K93,CONCATENATE("'",K93,"'"))),DATA_SOLICITUD!$L$1,IF(L93="NULL",L93,CONCATENATE("'",L93,"'"))) -> INSERT INTO `multitabla` (`id_multitabla`, `codigo_tabla`, `nombre_tabla`, `codigo`, `orden`, `valor`, `valor_aux`, `valor_crm`, `estado`, `estado_tabla`, `usuario_crea`, `fecha_crea`, `usuario_modif`, `fecha_modif`) VALUES (DEFAULT, '010', 'Nacionalidad', '91', '91', 'Paraguayo', '54', '538560012', '1', '1', 'admin', DEFAULT, NULL, NULL);
A94: DEFAULT | B94: 010 | C94: Nacionalidad | D94: 92 | E94: 92 | F94: Peruano | G94: 55 | H94: 538560003 | I94: NULL | J94: 1 | K94: 1 | L94: admin | M94: DEFAULT | N94: NULL | O94: NULL | P94: =SUBSTITUTE(SUBSTITUTE(SUBSTITUTE(SUBSTITUTE(SUBSTITUTE(SUBSTITUTE(SUBSTITUTE(SUBSTITUTE(SUBSTITUTE(SUBSTITUTE(SUBSTITUTE(INSERT!$B$3,DATA_SOLICITUD!$B$1,IF(B94="NULL",B94,CONCATENATE("'",B94,"'"))),DATA_SOLICITUD!$C$1,IF(C94="NULL",C94,CONCATENATE("'",C94,"'"))),DATA_SOLICITUD!$D$1,IF(D94="NULL",D94,CONCATENATE("'",D94,"'"))),DATA_SOLICITUD!$E$1,IF(E94="NULL",E94,CONCATENATE("'",E94,"'"))),DATA_SOLICITUD!$F$1,IF(F94="NULL",F94,CONCATENATE("'",F94,"'"))),DATA_SOLICITUD!$G$1,IF(G94="NULL",G94,CONCATENATE("'",G94,"'"))),DATA_SOLICITUD!$H$1,IF(H94="NULL",H94,CONCATENATE("'",H94,"'"))),DATA_SOLICITUD!$I$1,IF(I94="NULL",I94,CONCATENATE("'",I94,"'"))),DATA_SOLICITUD!$J$1,IF(J94="NULL",J94,CONCATENATE("'",J94,"'"))),DATA_SOLICITUD!$K$1,IF(K94="NULL",K94,CONCATENATE("'",K94,"'"))),DATA_SOLICITUD!$L$1,IF(L94="NULL",L94,CONCATENATE("'",L94,"'"))) -> INSERT INTO `multitabla` (`id_multitabla`, `codigo_tabla`, `nombre_tabla`, `codigo`, `orden`, `valor`, `valor_aux`, `valor_crm`, `estado`, `estado_tabla`, `usuario_crea`, `fecha_crea`, `usuario_modif`, `fecha_modif`) VALUES (DEFAULT, '010', 'Nacionalidad', '92', '92', 'Peruano', '55', '538560003', '1', '1', 'admin', DEFAULT, NULL, NULL);
A95: DEFAULT | B95: 010 | C95: Nacionalidad | D95: 93 | E95: 93 | F95: Polaco | G95: 56 | H95: 538560102 | I95: NULL | J95: 1 | K95: 1 | L95: admin | M95: DEFAULT | N95: NULL | O95: NULL | P95: =SUBSTITUTE(SUBSTITUTE(SUBSTITUTE(SUBSTITUTE(SUBSTITUTE(SUBSTITUTE(SUBSTITUTE(SUBSTITUTE(SUBSTITUTE(SUBSTITUTE(SUBSTITUTE(INSERT!$B$3,DATA_SOLICITUD!$B$1,IF(B95="NULL",B95,CONCATENATE("'",B95,"'"))),DATA_SOLICITUD!$C$1,IF(C95="NULL",C95,CONCATENATE("'",C95,"'"))),DATA_SOLICITUD!$D$1,IF(D95="NULL",D95,CONCATENATE("'",D95,"'"))),DATA_SOLICITUD!$E$1,IF(E95="NULL",E95,CONCATENATE("'",E95,"'"))),DATA_SOLICITUD!$F$1,IF(F95="NULL",F95,CONCATENATE("'",F95,"'"))),DATA_SOLICITUD!$G$1,IF(G95="NULL",G95,CONCATENATE("'",G95,"'"))),DATA_SOLICITUD!$H$1,IF(H95="NULL",H95,CONCATENATE("'",H95,"'"))),DATA_SOLICITUD!$I$1,IF(I95="NULL",I95,CONCATENATE("'",I95,"'"))),DATA_SOLICITUD!$J$1,IF(J95="NULL",J95,CONCATENATE("'",J95,"'"))),DATA_SOLICITUD!$K$1,IF(K95="NULL",K95,CONCATENATE("'",K95,"'"))),DATA_SOLICITUD!$L$1,IF(L95="NULL",L95,CONCATENATE("'",L95,"'"))) -> INSERT INTO `multitabla` (`id_multitabla`, `codigo_tabla`, `nombre_tabla`, `codigo`, `orden`, `valor`, `valor_aux`, `valor_crm`, `estado`, `estado_tabla`, `usuario_crea`, `fecha_crea`, `usuario_modif`, `fecha_modif`) VALUES (DEFAULT, '010', 'Nacionalidad', '93', '93', 'Polaco', '56', '538560102', '1', '1', 'admin', DEFAULT, NULL, NULL);
A96: DEFAULT | B96: 010 | C96: Nacionalidad | D96: 94 | E96: 94 | F96: Portugués | G96: 57 | H96: 538560103 | I96: NULL | J96: 1 | K96: 1 | L96: admin | M96: DEFAULT | N96: NULL | O96: NULL | P96: =SUBSTITUTE(SUBSTITUTE(SUBSTITUTE(SUBSTITUTE(SUBSTITUTE(SUBSTITUTE(SUBSTITUTE(SUBSTITUTE(SUBSTITUTE(SUBSTITUTE(SUBSTITUTE(INSERT!$B$3,DATA_SOLICITUD!$B$1,IF(B96="NULL",B96,CONCATENATE("'",B96,"'"))),DATA_SOLICITUD!$C$1,IF(C96="NULL",C96,CONCATENATE("'",C96,"'"))),DATA_SOLICITUD!$D$1,IF(D96="NULL",D96,CONCATENATE("'",D96,"'"))),DATA_SOLICITUD!$E$1,IF(E96="NULL",E96,CONCATENATE("'",E96,"'"))),DATA_SOLICITUD!$F$1,IF(F96="NULL",F96,CONCATENATE("'",F96,"'"))),DATA_SOLICITUD!$G$1,IF(G96="NULL",G96,CONCATENATE("'",G96,"'"))),DATA_SOLICITUD!$H$1,IF(H96="NULL",H96,CONCATENATE("'",H96,"'"))),DATA_SOLICITUD!$I$1,IF(I96="NULL",I96,CONCATENATE("'",I96,"'"))),DATA_SOLICITUD!$J$1,IF(J96="NULL",J96,CONCATENATE("'",J96,"'"))),DATA_SOLICITUD!$K$1,IF(K96="NULL",K96,CONCATENATE("'",K96,"'"))),DATA_SOLICITUD!$L$1,IF(L96="NULL",L96,CONCATENATE("'",L96,"'"))) -> INSERT INTO `multitabla` (`id_multitabla`, `codigo_tabla`, `nombre_tabla`, `codigo`, `orden`, `valor`, `valor_aux`, `valor_crm`, `estado`, `estado_tabla`, `usuario_crea`, `fecha_crea`, `usuario_modif`, `fecha_modif`) VALUES (DEFAULT, '010', 'Nacionalidad', '94', '94', 'Portugués', '57', '538560103', '1', '1', 'admin', DEFAULT, NULL, NULL);
A97: DEFAULT | B97: 010 | C97: Nacionalidad | D97: 95 | E97: 95 | F97: Puertorriqueño | G97: 58 | H97: 538560104 | I97: NULL | J97: 1 | K97: 1 | L97: admin | M97: DEFAULT | N97: NULL | O97: NULL | P97: =SUBSTITUTE(SUBSTITUTE(SUBSTITUTE(SUBSTITUTE(SUBSTITUTE(SUBSTITUTE(SUBSTITUTE(SUBSTITUTE(SUBSTITUTE(SUBSTITUTE(SUBSTITUTE(INSERT!$B$3,DATA_SOLICITUD!$B$1,IF(B97="NULL",B97,CONCATENATE("'",B97,"'"))),DATA_SOLICITUD!$C$1,IF(C97="NULL",C97,CONCATENATE("'",C97,"'"))),DATA_SOLICITUD!$D$1,IF(D97="NULL",D97,CONCATENATE("'",D97,"'"))),DATA_SOLICITUD!$E$1,IF(E97="NULL",E97,CONCATENATE("'",E97,"'"))),DATA_SOLICITUD!$F$1,IF(F97="NULL",F97,CONCATENATE("'",F97,"'"))),DATA_SOLICITUD!$G$1,IF(G97="NULL",G97,CONCATENATE("'",G97,"'"))),DATA_SOLICITUD!$H$1,IF(H97="NULL",H97,CONCATENATE("'",H97,"'"))),DATA_SOLICITUD!$I$1,IF(I97="NULL",I97,CONCATENATE("'",I97,"'"))),DATA_SOLICITUD!$J$1,IF(J97="NULL",J97,CONCATENATE("'",J97,"'"))),DATA_SOLICITUD!$K$1,IF(K97="NULL",K97,CONCATENATE("'",K97,"'"))),DATA_SOLICITUD!$L$1,IF(L97="NULL",L97,CONCATENATE("'",L97,"'"))) -> INSERT INTO `multitabla` (`id_multitabla`, `codigo_tabla`, `nombre_tabla`, `codigo`, `orden`, `valor`, `valor_aux`, `valor_crm`, `estado`, `estado_tabla`, `usuario_crea`, `fecha_crea`, `usuario_modif`, `fecha_modif`) VALUES (DEFAULT, '010', 'Nacionalidad', '95', '95', 'Puertorriqueño', '58', '538560104', '1', '1', 'admin', DEFAULT, NULL, NULL);
A98: DEFAULT | B98: 010 | C98: Nacionalidad | D98: 96 | E98: 96 | F98: Rumano | G98: 60 | H98: 538560105 | I98: NULL | J98: 1 | K98: 1 | L98: admin | M98: DEFAULT | N98: NULL | O98: NULL | P98: =SUBSTITUTE(SUBSTITUTE(SUBSTITUTE(SUBSTITUTE(SUBSTITUTE(SUBSTITUTE(SUBSTITUTE(SUBSTITUTE(SUBSTITUTE(SUBSTITUTE(SUBSTITUTE(INSERT!$B$3,DATA_SOLICITUD!$B$1,IF(B98="NULL",B98,CONCATENATE("'",B98,"'"))),DATA_SOLICITUD!$C$1,IF(C98="NULL",C98,CONCATENATE("'",C98,"'"))),DATA_SOLICITUD!$D$1,IF(D98="NULL",D98,CONCATENATE("'",D98,"'"))),DATA_SOLICITUD!$E$1,IF(E98="NULL",E98,CONCATENATE("'",E98,"'"))),DATA_SOLICITUD!$F$1,IF(F98="NULL",F98,CONCATENATE("'",F98,"'"))),DATA_SOLICITUD!$G$1,IF(G98="NULL",G98,CONCATENATE("'",G98,"'"))),DATA_SOLICITUD!$H$1,IF(H98="NULL",H98,CONCATENATE("'",H98,"'"))),DATA_SOLICITUD!$I$1,IF(I98="NULL",I98,CONCATENATE("'",I98,"'"))),DATA_SOLICITUD!$J$1,IF(J98="NULL",J98,CONCATENATE("'",J98,"'"))),DATA_SOLICITUD!$K$1,IF(K98="NULL",K98,CONCATENATE("'",K98,"'"))),DATA_SOLICITUD!$L$1,IF(L98="NULL",L98,CONCATENATE("'",L98,"'"))) -> INSERT INTO `multitabla` (`id_multitabla`, `codigo_tabla`, `nombre_tabla`, `codigo`, `orden`, `valor`, `valor_aux`, `valor_crm`, `estado`, `estado_tabla`, `usuario_crea`, `fecha_crea`, `usuario_modif`, `fecha_modif`) VALUES (DEFAULT, '010', 'Nacionalidad', '96', '96', 'Rumano', '60', '538560105', '1', '1', 'admin', DEFAULT, NULL, NULL);
A99: DEFAULT | B99: 010 | C99: Nacionalidad | D99: 97 | E99: 97 | F99: Rusa | G99: 130 | H99: 538560106 | I99: NULL | J99: 1 | K99: 1 | L99: admin | M99: DEFAULT | N99: NULL | O99: NULL | P99: =SUBSTITUTE(SUBSTITUTE(SUBSTITUTE(SUBSTITUTE(SUBSTITUTE(SUBSTITUTE(SUBSTITUTE(SUBSTITUTE(SUBSTITUTE(SUBSTITUTE(SUBSTITUTE(INSERT!$B$3,DATA_SOLICITUD!$B$1,IF(B99="NULL",B99,CONCATENATE("'",B99,"'"))),DATA_SOLICITUD!$C$1,IF(C99="NULL",C99,CONCATENATE("'",C99,"'"))),DATA_SOLICITUD!$D$1,IF(D99="NULL",D99,CONCATENATE("'",D99,"'"))),DATA_SOLICITUD!$E$1,IF(E99="NULL",E99,CONCATENATE("'",E99,"'"))),DATA_SOLICITUD!$F$1,IF(F99="NULL",F99,CONCATENATE("'",F99,"'"))),DATA_SOLICITUD!$G$1,IF(G99="NULL",G99,CONCATENATE("'",G99,"'"))),DATA_SOLICITUD!$H$1,IF(H99="NULL",H99,CONCATENATE("'",H99,"'"))),DATA_SOLICITUD!$I$1,IF(I99="NULL",I99,CONCATENATE("'",I99,"'"))),DATA_SOLICITUD!$J$1,IF(J99="NULL",J99,CONCATENATE("'",J99,"'"))),DATA_SOLICITUD!$K$1,IF(K99="NULL",K99,CONCATENATE("'",K99,"'"))),DATA_SOLICITUD!$L$1,IF(L99="NULL",L99,CONCATENATE("'",L99,"'"))) -> INSERT INTO `multitabla` (`id_multitabla`, `codigo_tabla`, `nombre_tabla`, `codigo`, `orden`, `valor`, `valor_aux`, `valor_crm`, `estado`, `estado_tabla`, `usuario_crea`, `fecha_crea`, `usuario_modif`, `fecha_modif`) VALUES (DEFAULT, '010', 'Nacionalidad', '97', '97', 'Rusa', '130', '538560106', '1', '1', 'admin', DEFAULT, NULL, NULL);
A100: DEFAULT | B100: 010 | C100: Nacionalidad | D100: 98 | E100: 98 | F100: Salvadoreño | G100: 20 | H100: 538560108 | I100: NULL | J100: 1 | K100: 1 | L100: admin | M100: DEFAULT | N100: NULL | O100: NULL | P100: =SUBSTITUTE(SUBSTITUTE(SUBSTITUTE(SUBSTITUTE(SUBSTITUTE(SUBSTITUTE(SUBSTITUTE(SUBSTITUTE(SUBSTITUTE(SUBSTITUTE(SUBSTITUTE(INSERT!$B$3,DATA_SOLICITUD!$B$1,IF(B100="NULL",B100,CONCATENATE("'",B100,"'"))),DATA_SOLICITUD!$C$1,IF(C100="NULL",C100,CONCATENATE("'",C100,"'"))),DATA_SOLICITUD!$D$1,IF(D100="NULL",D100,CONCATENATE("'",D100,"'"))),DATA_SOLICITUD!$E$1,IF(E100="NULL",E100,CONCATENATE("'",E100,"'"))),DATA_SOLICITUD!$F$1,IF(F100="NULL",F100,CONCATENATE("'",F100,"'"))),DATA_SOLICITUD!$G$1,IF(G100="NULL",G100,CONCATENATE("'",G100,"'"))),DATA_SOLICITUD!$H$1,IF(H100="NULL",H100,CONCATENATE("'",H100,"'"))),DATA_SOLICITUD!$I$1,IF(I100="NULL",I100,CONCATENATE("'",I100,"'"))),DATA_SOLICITUD!$J$1,IF(J100="NULL",J100,CONCATENATE("'",J100,"'"))),DATA_SOLICITUD!$K$1,IF(K100="NULL",K100,CONCATENATE("'",K100,"'"))),DATA_SOLICITUD!$L$1,IF(L100="NULL",L100,CONCATENATE("'",L100,"'"))) -> INSERT INTO `multitabla` (`id_multitabla`, `codigo_tabla`, `nombre_tabla`, `codigo`, `orden`, `valor`, `valor_aux`, `valor_crm`, `estado`, `estado_tabla`, `usuario_crea`, `fecha_crea`, `usuario_modif`, `fecha_modif`) VALUES (DEFAULT, '010', 'Nacionalidad', '98', '98', 'Salvadoreño', '20', '538560108', '1', '1', 'admin', DEFAULT, NULL, NULL);
A101: DEFAULT | B101: 010 | C101: Nacionalidad | D101: 99 | E101: 99 | F101: Samboana | G101: 81 | H101: 538560109 | I101: NULL | J101: 1 | K101: 1 | L101: admin | M101: DEFAULT | N101: NULL | O101: NULL | P101: =SUBSTITUTE(SUBSTITUTE(SUBSTITUTE(SUBSTITUTE(SUBSTITUTE(SUBSTITUTE(SUBSTITUTE(SUBSTITUTE(SUBSTITUTE(SUBSTITUTE(SUBSTITUTE(INSERT!$B$3,DATA_SOLICITUD!$B$1,IF(B101="NULL",B101,CONCATENATE("'",B101,"'"))),DATA_SOLICITUD!$C$1,IF(C101="NULL",C101,CONCATENATE("'",C101,"'"))),DATA_SOLICITUD!$D$1,IF(D101="NULL",D101,CONCATENATE("'",D101,"'"))),DATA_SOLICITUD!$E$1,IF(E101="NULL",E101,CONCATENATE("'",E101,"'"))),DATA_SOLICITUD!$F$1,IF(F101="NULL",F101,CONCATENATE("'",F101,"'"))),DATA_SOLICITUD!$G$1,IF(G101="NULL",G101,CONCATENATE("'",G101,"'"))),DATA_SOLICITUD!$H$1,IF(H101="NULL",H101,CONCATENATE("'",H101,"'"))),DATA_SOLICITUD!$I$1,IF(I101="NULL",I101,CONCATENATE("'",I101,"'"))),DATA_SOLICITUD!$J$1,IF(J101="NULL",J101,CONCATENATE("'",J101,"'"))),DATA_SOLICITUD!$K$1,IF(K101="NULL",K101,CONCATENATE("'",K101,"'"))),DATA_SOLICITUD!$L$1,IF(L101="NULL",L101,CONCATENATE("'",L101,"'"))) -> INSERT INTO `multitabla` (`id_multitabla`, `codigo_tabla`, `nombre_tabla`, `codigo`, `orden`, `valor`, `valor_aux`, `valor_crm`, `estado`, `estado_tabla`, `usuario_crea`, `fecha_crea`, `usuario_modif`, `fecha_modif`) VALUES (DEFAULT, '010', 'Nacionalidad', '99', '99', 'Samboana', '81', '538560109', '1', '1', 'admin', DEFAULT, NULL, NULL);
A102: DEFAULT | B102: 010 | C102: Nacionalidad | D102: 100 | E102: 100 | F102: Samoana Estadounidense | G102: 112 | H102: 538560110 | I102: NULL | J102: 1 | K102: 1 | L102: admin | M102: DEFAULT | N102: NULL | O102: NULL | P102: =SUBSTITUTE(SUBSTITUTE(SUBSTITUTE(SUBSTITUTE(SUBSTITUTE(SUBSTITUTE(SUBSTITUTE(SUBSTITUTE(SUBSTITUTE(SUBSTITUTE(SUBSTITUTE(INSERT!$B$3,DATA_SOLICITUD!$B$1,IF(B102="NULL",B102,CONCATENATE("'",B102,"'"))),DATA_SOLICITUD!$C$1,IF(C102="NULL",C102,CONCATENATE("'",C102,"'"))),DATA_SOLICITUD!$D$1,IF(D102="NULL",D102,CONCATENATE("'",D102,"'"))),DATA_SOLICITUD!$E$1,IF(E102="NULL",E102,CONCATENATE("'",E102,"'"))),DATA_SOLICITUD!$F$1,IF(F102="NULL",F102,CONCATENATE("'",F102,"'"))),DATA_SOLICITUD!$G$1,IF(G102="NULL",G102,CONCATENATE("'",G102,"'"))),DATA_SOLICITUD!$H$1,IF(H102="NULL",H102,CONCATENATE("'",H102,"'"))),DATA_SOLICITUD!$I$1,IF(I102="NULL",I102,CONCATENATE("'",I102,"'"))),DATA_SOLICITUD!$J$1,IF(J102="NULL",J102,CONCATENATE("'",J102,"'"))),DATA_SOLICITUD!$K$1,IF(K102="NULL",K102,CONCATENATE("'",K102,"'"))),DATA_SOLICITUD!$L$1,IF(L102="NULL",L102,CONCATENATE("'",L102,"'"))) -> INSERT INTO `multitabla` (`id_multitabla`, `codigo_tabla`, `nombre_tabla`, `codigo`, `orden`, `valor`, `valor_aux`, `valor_crm`, `estado`, `estado_tabla`, `usuario_crea`, `fecha_crea`, `usuario_modif`, `fecha_modif`) VALUES (DEFAULT, '010', 'Nacionalidad', '100', '100', 'Samoana Estadounidense', '112', '538560110', '1', '1', 'admin', DEFAULT, NULL, NULL);
A103: DEFAULT | B103: 010 | C103: Nacionalidad | D103: 101 | E103: 101 | F103: Sancristobaleña | G103: 82 | H103: 538560111 | I103: NULL | J103: 1 | K103: 1 | L103: admin | M103: DEFAULT | N103: NULL | O103: NULL | P103: =SUBSTITUTE(SUBSTITUTE(SUBSTITUTE(SUBSTITUTE(SUBSTITUTE(SUBSTITUTE(SUBSTITUTE(SUBSTITUTE(SUBSTITUTE(SUBSTITUTE(SUBSTITUTE(INSERT!$B$3,DATA_SOLICITUD!$B$1,IF(B103="NULL",B103,CONCATENATE("'",B103,"'"))),DATA_SOLICITUD!$C$1,IF(C103="NULL",C103,CONCATENATE("'",C103,"'"))),DATA_SOLICITUD!$D$1,IF(D103="NULL",D103,CONCATENATE("'",D103,"'"))),DATA_SOLICITUD!$E$1,IF(E103="NULL",E103,CONCATENATE("'",E103,"'"))),DATA_SOLICITUD!$F$1,IF(F103="NULL",F103,CONCATENATE("'",F103,"'"))),DATA_SOLICITUD!$G$1,IF(G103="NULL",G103,CONCATENATE("'",G103,"'"))),DATA_SOLICITUD!$H$1,IF(H103="NULL",H103,CONCATENATE("'",H103,"'"))),DATA_SOLICITUD!$I$1,IF(I103="NULL",I103,CONCATENATE("'",I103,"'"))),DATA_SOLICITUD!$J$1,IF(J103="NULL",J103,CONCATENATE("'",J103,"'"))),DATA_SOLICITUD!$K$1,IF(K103="NULL",K103,CONCATENATE("'",K103,"'"))),DATA_SOLICITUD!$L$1,IF(L103="NULL",L103,CONCATENATE("'",L103,"'"))) -> INSERT INTO `multitabla` (`id_multitabla`, `codigo_tabla`, `nombre_tabla`, `codigo`, `orden`, `valor`, `valor_aux`, `valor_crm`, `estado`, `estado_tabla`, `usuario_crea`, `fecha_crea`, `usuario_modif`, `fecha_modif`) VALUES (DEFAULT, '010', 'Nacionalidad', '101', '101', 'Sancristobaleña', '82', '538560111', '1', '1', 'admin', DEFAULT, NULL, NULL);
... A127: DEFAULT | B127: 010 | C127: Nacionalidad | D127: 125 | E127: 125 | F127: Zimbabuense | G127: 133 | H127: 538560135 | I127: NULL | J127: 1 | K127: 1 | L127: admin | M127: DEFAULT | N127: NULL | O127: NULL | P127: =SUBSTITUTE(SUBSTITUTE(SUBSTITUTE(SUBSTITUTE(SUBSTITUTE(SUBSTITUTE(SUBSTITUTE(SUBSTITUTE(SUBSTITUTE(SUBSTITUTE(SUBSTITUTE(INSERT!$B$3,DATA_SOLICITUD!$B$1,IF(B127="NULL",B127,CONCATENATE("'",B127,"'"))),DATA_SOLICITUD!$C$1,IF(C127="NULL",C127,CONCATENATE("'",C127,"'"))),DATA_SOLICITUD!$D$1,IF(D127="NULL",D127,CONCATENATE("'",D127,"'"))),DATA_SOLICITUD!$E$1,IF(E127="NULL",E127,CONCATENATE("'",E127,"'"))),DATA_SOLICITUD!$F$1,IF(F127="NULL",F127,CONCATENATE("'",F127,"'"))),DATA_SOLICITUD!$G$1,IF(G127="NULL",G127,CONCATENATE("'",G127,"'"))),DATA_SOLICITUD!$H$1,IF(H127="NULL",H127,CONCATENATE("'",H127,"'"))),DATA_SOLICITUD!$I$1,IF(I127="NULL",I127,CONCATENATE("'",I127,"'"))),DATA_SOLICITUD!$J$1,IF(J127="NULL",J127,CONCATENATE("'",J127,"'"))),DATA_SOLICITUD!$K$1,IF(K127="NULL",K127,CONCATENATE("'",K127,"'"))),DATA_SOLICITUD!$L$1,IF(L127="NULL",L127,CONCATENATE("'",L127,"'"))) -> INSERT INTO `multitabla` (`id_multitabla`, `codigo_tabla`, `nombre_tabla`, `codigo`, `orden`, `valor`, `valor_aux`, `valor_crm`, `estado`, `estado_tabla`, `usuario_crea`, `fecha_crea`, `usuario_modif`, `fecha_modif`) VALUES (DEFAULT, '010', 'Nacionalidad', '125', '125', 'Zimbabuense', '133', '538560135', '1', '1', 'admin', DEFAULT, NULL, NULL);
A128: DEFAULT | B128: 011 | C128: Estado Solicitud | D128: NULL | E128: NULL | F128: NULL | G128: NULL | H128: NULL | I128: NULL | J128: NULL | K128: 1 | L128: admin | M128: DEFAULT | N128: NULL | O128: NULL | P128: =SUBSTITUTE(SUBSTITUTE(SUBSTITUTE(SUBSTITUTE(SUBSTITUTE(SUBSTITUTE(SUBSTITUTE(SUBSTITUTE(SUBSTITUTE(SUBSTITUTE(SUBSTITUTE(INSERT!$B$3,DATA_SOLICITUD!$B$1,IF(B128="NULL",B128,CONCATENATE("'",B128,"'"))),DATA_SOLICITUD!$C$1,IF(C128="NULL",C128,CONCATENATE("'",C128,"'"))),DATA_SOLICITUD!$D$1,IF(D128="NULL",D128,CONCATENATE("'",D128,"'"))),DATA_SOLICITUD!$E$1,IF(E128="NULL",E128,CONCATENATE("'",E128,"'"))),DATA_SOLICITUD!$F$1,IF(F128="NULL",F128,CONCATENATE("'",F128,"'"))),DATA_SOLICITUD!$G$1,IF(G128="NULL",G128,CONCATENATE("'",G128,"'"))),DATA_SOLICITUD!$H$1,IF(H128="NULL",H128,CONCATENATE("'",H128,"'"))),DATA_SOLICITUD!$I$1,IF(I128="NULL",I128,CONCATENATE("'",I128,"'"))),DATA_SOLICITUD!$J$1,IF(J128="NULL",J128,CONCATENATE("'",J128,"'"))),DATA_SOLICITUD!$K$1,IF(K128="NULL",K128,CONCATENATE("'",K128,"'"))),DATA_SOLICITUD!$L$1,IF(L128="NULL",L128,CONCATENATE("'",L128,"'"))) -> INSERT INTO `multitabla` (`id_multitabla`, `codigo_tabla`, `nombre_tabla`, `codigo`, `orden`, `valor`, `valor_aux`, `valor_crm`, `estado`, `estado_tabla`, `usuario_crea`, `fecha_crea`, `usuario_modif`, `fecha_modif`) VALUES (DEFAULT, '011', 'Estado Solicitud', NULL, NULL, NULL, NULL, NULL, NULL, '1', 'admin', DEFAULT, NULL, NULL);
A129: DEFAULT | B129: 011 | C129: Estado Solicitud | D129: 1 | E129: 1 | F129: Pendiente | G129: NULL | H129: NULL | I129: NULL | J129: 1 | K129: 1 | L129: admin | M129: DEFAULT | N129: NULL | O129: NULL | P129: =SUBSTITUTE(SUBSTITUTE(SUBSTITUTE(SUBSTITUTE(SUBSTITUTE(SUBSTITUTE(SUBSTITUTE(SUBSTITUTE(SUBSTITUTE(SUBSTITUTE(SUBSTITUTE(INSERT!$B$3,DATA_SOLICITUD!$B$1,IF(B129="NULL",B129,CONCATENATE("'",B129,"'"))),DATA_SOLICITUD!$C$1,IF(C129="NULL",C129,CONCATENATE("'",C129,"'"))),DATA_SOLICITUD!$D$1,IF(D129="NULL",D129,CONCATENATE("'",D129,"'"))),DATA_SOLICITUD!$E$1,IF(E129="NULL",E129,CONCATENATE("'",E129,"'"))),DATA_SOLICITUD!$F$1,IF(F129="NULL",F129,CONCATENATE("'",F129,"'"))),DATA_SOLICITUD!$G$1,IF(G129="NULL",G129,CONCATENATE("'",G129,"'"))),DATA_SOLICITUD!$H$1,IF(H129="NULL",H129,CONCATENATE("'",H129,"'"))),DATA_SOLICITUD!$I$1,IF(I129="NULL",I129,CONCATENATE("'",I129,"'"))),DATA_SOLICITUD!$J$1,IF(J129="NULL",J129,CONCATENATE("'",J129,"'"))),DATA_SOLICITUD!$K$1,IF(K129="NULL",K129,CONCATENATE("'",K129,"'"))),DATA_SOLICITUD!$L$1,IF(L129="NULL",L129,CONCATENATE("'",L129,"'"))) -> INSERT INTO `multitabla` (`id_multitabla`, `codigo_tabla`, `nombre_tabla`, `codigo`, `orden`, `valor`, `valor_aux`, `valor_crm`, `estado`, `estado_tabla`, `usuario_crea`, `fecha_crea`, `usuario_modif`, `fecha_modif`) VALUES (DEFAULT, '011', 'Estado Solicitud', '1', '1', 'Pendiente', NULL, NULL, '1', '1', 'admin', DEFAULT, NULL, NULL);
